Workbook

Sheet Read me
B1: DataCapture – PostgreSQL volume projection 2027–2031 (225,000 files in 2027, +10%/year, 2 MB PDF)
B2: PostgreSQL 15.10 database “dcdb” – DBA audit – October 2026 – v3
B4: Object
B5: Project the volume of the DataCapture database and of COS object storage over 2027–2031: 225,000 PDF files in 2027, 10% annual growth, 2 MB average PDF size. Size disk, backup and restore.
B6: PDFs and extraction JSON files are stored in COS (columns link / output_file_path): PostgreSQL only holds metadata.
B7: The norm table is excluded from the scope.
B9: Row size calculation method (“Row size calc” sheet)
B10: 1. Tuple header: 23 bytes + NULL bitmap (1 bit per column, only if at least one column is NULL), rounded up to a multiple of 8.
B11: 2. Each column, in DDL order: alignment padding (bigint/timestamp = 8, integer/enum = 4, long varlena = 4) then stored size. A NULL column takes no bytes.
B12: 3. Text (varchar, text, domains): 1 header byte + number of characters if ≤ 126 bytes (short varlena, no alignment); otherwise 4 header bytes + data, aligned on 4.
B13: 4. Tuple size = end of the last column rounded up to a multiple of 8 (MAXALIGN). Add 4 bytes of line pointer (ItemId).
B14: 5. Rows per page = INT((8,192 − 24) / (tuple + 4)). Effective row size = 8,192 / rows per page (includes the space lost at the end of the page).
... B20: Run the queries of the “Collection queries” sheet, enter the measurements in the yellow columns of “Table analysis” and adjust text lengths in “Row size calc” (SELECT avg(octet_length(column)) FROM table).

Sheet Assumptions
A1: Model assumptions
A2: Blue cells on yellow: editable. All projections depend on them.
A3: Parameter | B3: Value | C3: Unit | D3: Source / comment
A4: Business volume
A5: PDF files received – year 1 (2027) | B5: 225000 | C5: PDF/year | D5: Provided
A6: Annual growth of the flow | B6: 0.1 | C6: %/year | D6: Agreed assumption: +10% per year from 2028
A7: Projection horizon | B7: 5 | C7: years | D7: Provided
A8: Reference year (current state) | B8: 2026 | C8: year | D8: Audit date
A9: Average PDF size | B9: 2 | C9: MB | D9: Agreed assumption (to be confirmed: SELECT avg(size)/1048576 FROM metadata;)
A10: Average size of an extraction JSON (COS) | B10: 30 | C10: KB | D10: ASSUMPTION
A11: PostgreSQL database
A12: Current database size | B12: 50 | C12: MB | D12: Provided
A13: Share of indexes in the current size | B13: 0.35 | C13: % | D13: ASSUMPTION – to be measured (query Q1)
A14: submission_status_history rows per file | B14: 8 | C14: rows | D14: ASSUMPTION – status transitions per file (measure: Q11)
A15: Bloat factor (MVCC, partly filled pages) | B15: 1.2 | C15: x | D15: Repeated status updates on submissions; 1.2 = 20% dead space at steady state
A16: PostgreSQL page size | B16: 8192 | C16: bytes | D16: Standard BLCKSZ
A17: Heap page header | B17: 24 | C17: bytes | D17: PageHeaderData
A18: B-tree page special area | B18: 16 | C18: bytes | D18: BTPageOpaqueData
A19: B-tree index fillfactor | B19: 0.9 | C19: % | D19: PostgreSQL default
A20: Spring Batch
A21: Spring Batch job executions per day | B21: 192 | C21: exec./day | D21: ASSUMPTION – 2 jobs every 15 min (frequency to be defined, minutes of 28/10/2026)
A22: Parameters per execution | B22: 2 | C22: rows | D22: ASSUMPTION – e.g. run.id + execution date
A23: Steps per execution | B23: 1 | C23: rows | D23: ASSUMPTION – one chunk step per job
A24: Recommended Spring Batch retention | B24: 90 | C24: days | D24: Audit recommendation
A25: Backup / restore
A26: Backup compression ratio | B26: 0.3 | C26: % | D26: ASSUMPTION – compressed pgBackRest/pg_dump
A27: Full backups kept | B27: 14 | C27: copies | D27: ASSUMPTION – 1 full/day for 14 days
A28: WAL archived per day | B28: 0.05 | C28: % of DB | D28: ASSUMPTION
A29: WAL retention (PITR) | B29: 14 | C29: days | D29: Aligned with fulls
A30: Restore throughput | B30: 100 | C30: MB/s | D30: ASSUMPTION – SSD / 1 Gb/s network
A31: Capacity planning
A32: Disk margin (multiplier) | B32: 2 | C32: x | D32: VACUUM FULL / pg_repack / REINDEX require a copy of the table
A33: pg_wal reserve | B33: 8 | C33: GB | D33: 2 × recommended max_wal_size (4 GB)
A34: Alert threshold (warning) | B34: 0.7 | C34: % of disk | D34: Operations standard
A35: Critical threshold | B35: 0.85 | C35: % of disk | D35: Operations standard
A36: COS storage margin | B36: 0.2 | C36: % | D36: ASSUMPTION
A37: Roadmap costing
A38: Average daily rate (DBA / developer) | B38: 700 | C38: €/j.h | D38: ASSUMPTION
A40: Intermediate results (calculated)
A41: Data bytes per file (5 business tables) | B41: =('Table analysis'!C5*'Table analysis'!D5+'Table analysis'!C6*'Table analysis'!D6+'Table analysis'!C7*'Table analysis'!D7+'Table analysis'!C8*'Table analysis'!D8+'Table analysis'!C9*'Table analysis'!D9) -> 1473.8952 | C41: bytes | D41: Weighted sum from the Table analysis sheet
...

Sheet Row size calc
A1: Detailed row size calculation – table by table, column by column
A2: PostgreSQL rules: 23 B header + NULL bitmap (if any NULL) rounded to 8 · NULL column = 0 B · short varlena (≤ 126 B of data) = 1 B header, no alignment · long varlena = 4 B header, aligned on 4 · bigint/timestamp aligned on 8 · integer/ENUM aligned on 4 · tuple rounded to 8 · + 4 B line pointer.
A4: Table submissions
A5: Table | B5: N° | C5: Column | D5: PostgreSQL type | E5: Storage | F5: Type alignment (B) | G5: Fixed length (B) | H5: Typical content (assumption) | I5: No. of characters | J5: NULL? | K5: Effective alignment (B) | L5: Start offset (B) | M5: Padding (B) | N5: Stored size (B) / end offset
A6: submissions | C6: Step 1 – tuple header | D6: 12 columns | H6: 23 B + NULL bitmap (ROUNDUP(no. of columns/8)) if at least one column is NULL, rounded up to a multiple of 8 | N6: =ROUNDUP((23+IF(COUNTIF(J7:J18,"Y")>0,ROUNDUP(12/8,0),0))/8,0)*8 -> 24
A7: submissions | B7: 1 | C7: id | D7: bigint | E7: fixed | F7: 8 | G7: 8 | H7: Identifier from submissions_sequence | I7: — | J7: N | K7: =IF(J7="Y",1,IF(E7="fixed",F7,IF(I7+1<=127,1,F7))) -> 8 | L7: =N6 -> 24 | M7: =IF(J7="Y",0,MOD(K7-MOD(L7,K7),K7)) -> 0 | N7: =L7+M7+IF(J7="Y",0,IF(E7="fixed",G7,IF(I7+1<=127,I7+1,I7+4))) -> 32 | O7: =IF(J7="Y",0,IF(E7="fixed",G7,IF(I7+1<=127,I7+1,I7+4))) -> 8
A8: submissions | B8: 2 | C8: uuid | D8: varchar(40) | E8: varlena | F8: 4 | G8: — | H8: UUID v4 in text format | I8: 36 | J8: N | K8: =IF(J8="Y",1,IF(E8="fixed",F8,IF(I8+1<=127,1,F8))) -> 1 | L8: =N7 -> 32 | M8: =IF(J8="Y",0,MOD(K8-MOD(L8,K8),K8)) -> 0 | N8: =L8+M8+IF(J8="Y",0,IF(E8="fixed",G8,IF(I8+1<=127,I8+1,I8+4))) -> 69 | O8: =IF(J8="Y",0,IF(E8="fixed",G8,IF(I8+1<=127,I8+1,I8+4))) -> 37
A9: submissions | B9: 3 | C9: link | D9: text | E9: varlena | F9: 4 | G9: — | H9: URL of the PDF object in COS | I9: 80 | J9: N | K9: =IF(J9="Y",1,IF(E9="fixed",F9,IF(I9+1<=127,1,F9))) -> 1 | L9: =N8 -> 69 | M9: =IF(J9="Y",0,MOD(K9-MOD(L9,K9),K9)) -> 0 | N9: =L9+M9+IF(J9="Y",0,IF(E9="fixed",G9,IF(I9+1<=127,I9+1,I9+4))) -> 150 | O9: =IF(J9="Y",0,IF(E9="fixed",G9,IF(I9+1<=127,I9+1,I9+4))) -> 81
A10: submissions | B10: 4 | C10: status | D10: submission_status (ENUM) | E10: fixed | F10: 4 | G10: 4 | H10: ENUM = 4-byte OID | I10: — | J10: N | K10: =IF(J10="Y",1,IF(E10="fixed",F10,IF(I10+1<=127,1,F10))) -> 4 | L10: =N9 -> 150 | M10: =IF(J10="Y",0,MOD(K10-MOD(L10,K10),K10)) -> 2 | N10: =L10+M10+IF(J10="Y",0,IF(E10="fixed",G10,IF(I10+1<=127,I10+1,I10+4))) -> 156 | O10: =IF(J10="Y",0,IF(E10="fixed",G10,IF(I10+1<=127,I10+1,I10+4))) -> 4
A11: submissions | B11: 5 | C11: upload_ts | D11: timestamp(3) | E11: fixed | F11: 8 | G11: 8 | H11: Timestamp | I11: — | J11: N | K11: =IF(J11="Y",1,IF(E11="fixed",F11,IF(I11+1<=127,1,F11))) -> 8 | L11: =N10 -> 156 | M11: =IF(J11="Y",0,MOD(K11-MOD(L11,K11),K11)) -> 4 | N11: =L11+M11+IF(J11="Y",0,IF(E11="fixed",G11,IF(I11+1<=127,I11+1,I11+4))) -> 168 | O11: =IF(J11="Y",0,IF(E11="fixed",G11,IF(I11+1<=127,I11+1,I11+4))) -> 8
A12: submissions | B12: 6 | C12: source | D12: source_provider (varchar(20)) | E12: varlena | F12: 4 | G12: — | H12: 'API' / 'UI' / 'CFT' | I12: 3 | J12: N | K12: =IF(J12="Y",1,IF(E12="fixed",F12,IF(I12+1<=127,1,F12))) -> 1 | L12: =N11 -> 168 | M12: =IF(J12="Y",0,MOD(K12-MOD(L12,K12),K12)) -> 0 | N12: =L12+M12+IF(J12="Y",0,IF(E12="fixed",G12,IF(I12+1<=127,I12+1,I12+4))) -> 172 | O12: =IF(J12="Y",0,IF(E12="fixed",G12,IF(I12+1<=127,I12+1,I12+4))) -> 4
A13: submissions | B13: 7 | C13: filename | D13: text | E13: varlena | F13: 4 | G13: — | H13: Original file name | I13: 40 | J13: N | K13: =IF(J13="Y",1,IF(E13="fixed",F13,IF(I13+1<=127,1,F13))) -> 1 | L13: =N12 -> 172 | M13: =IF(J13="Y",0,MOD(K13-MOD(L13,K13),K13)) -> 0 | N13: =L13+M13+IF(J13="Y",0,IF(E13="fixed",G13,IF(I13+1<=127,I13+1,I13+4))) -> 213 | O13: =IF(J13="Y",0,IF(E13="fixed",G13,IF(I13+1<=127,I13+1,I13+4))) -> 41
A14: submissions | B14: 8 | C14: processing_status | D14: processing_status (ENUM) | E14: fixed | F14: 4 | G14: 4 | H14: ENUM = 4-byte OID | I14: — | J14: N | K14: =IF(J14="Y",1,IF(E14="fixed",F14,IF(I14+1<=127,1,F14))) -> 4 | L14: =N13 -> 213 | M14: =IF(J14="Y",0,MOD(K14-MOD(L14,K14),K14)) -> 3 | N14: =L14+M14+IF(J14="Y",0,IF(E14="fixed",G14,IF(I14+1<=127,I14+1,I14+4))) -> 220 | O14: =IF(J14="Y",0,IF(E14="fixed",G14,IF(I14+1<=127,I14+1,I14+4))) -> 4
A15: submissions | B15: 9 | C15: metadata_id | D15: bigint | E15: fixed | F15: 8 | G15: 8 | H15: FK to metadata | I15: — | J15: N | K15: =IF(J15="Y",1,IF(E15="fixed",F15,IF(I15+1<=127,1,F15))) -> 8 | L15: =N14 -> 220 | M15: =IF(J15="Y",0,MOD(K15-MOD(L15,K15),K15)) -> 4 | N15: =L15+M15+IF(J15="Y",0,IF(E15="fixed",G15,IF(I15+1<=127,I15+1,I15+4))) -> 232 | O15: =IF(J15="Y",0,IF(E15="fixed",G15,IF(I15+1<=127,I15+1,I15+4))) -> 8
A16: submissions | B16: 10 | C16: pre_processing_step_id | D16: bigint | E16: fixed | F16: 8 | G16: 8 | H16: FK to preprocessing_steps | I16: — | J16: N | K16: =IF(J16="Y",1,IF(E16="fixed",F16,IF(I16+1<=127,1,F16))) -> 8 | L16: =N15 -> 232 | M16: =IF(J16="Y",0,MOD(K16-MOD(L16,K16),K16)) -> 0 | N16: =L16+M16+IF(J16="Y",0,IF(E16="fixed",G16,IF(I16+1<=127,I16+1,I16+4))) -> 240 | O16: =IF(J16="Y",0,IF(E16="fixed",G16,IF(I16+1<=127,I16+1,I16+4))) -> 8
A17: submissions | B17: 11 | C17: extraction_step_id | D17: bigint | E17: fixed | F17: 8 | G17: 8 | H17: FK to extraction_steps | I17: — | J17: N | K17: =IF(J17="Y",1,IF(E17="fixed",F17,IF(I17+1<=127,1,F17))) -> 8 | L17: =N16 -> 240 | M17: =IF(J17="Y",0,MOD(K17-MOD(L17,K17),K17)) -> 0 | N17: =L17+M17+IF(J17="Y",0,IF(E17="fixed",G17,IF(I17+1<=127,I17+1,I17+4))) -> 248 | O17: =IF(J17="Y",0,IF(E17="fixed",G17,IF(I17+1<=127,I17+1,I17+4))) -> 8
A18: submissions | B18: 12 | C18: user_id | D18: varchar(40) | E18: varlena | F18: 4 | G18: — | H18: User identifier (e.g. j59209) | I18: 8 | J18: N | K18: =IF(J18="Y",1,IF(E18="fixed",F18,IF(I18+1<=127,1,F18))) -> 1 | L18: =N17 -> 248 | M18: =IF(J18="Y",0,MOD(K18-MOD(L18,K18),K18)) -> 0 | N18: =L18+M18+IF(J18="Y",0,IF(E18="fixed",G18,IF(I18+1<=127,I18+1,I18+4))) -> 257 | O18: =IF(J18="Y",0,IF(E18="fixed",G18,IF(I18+1<=127,I18+1,I18+4))) -> 9
C19: Step 2 – sum of the stored column sizes (B) | N19: =SUM(O7:O18) -> 220
C20: Step 2 – sum of alignment padding (B) | N20: =SUM(M7:M18) -> 13
C21: Step 3 – end of the last column (B) | N21: =N18 -> 257
C22: Step 4 – tuple aligned to MAXALIGN 8 (B) | N22: =ROUNDUP(N18/8,0)*8 -> 264
C23: Step 4 – + ItemId line pointer (B) | N23: =N22+4 -> 268
C24: Step 5 – rows per 8 KB page | N24: =INT((Assumptions!$B$16-Assumptions!$B$17)/N23) -> 30
C25: Step 5 – EFFECTIVE ROW SIZE (B) | N25: =Assumptions!$B$16/N24 -> 273.06667
A28: Table submission_status_history
A29: Table | B29: N° | C29: Column | D29: PostgreSQL type | E29: Storage | F29: Type alignment (B) | G29: Fixed length (B) | H29: Typical content (assumption) | I29: No. of characters | J29: NULL? | K29: Effective alignment (B) | L29: Start offset (B) | M29: Padding (B) | N29: Stored size (B) / end offset
A30: submission_status_history | C30: Step 1 – tuple header | D30: 6 columns | H30: 23 B + NULL bitmap (ROUNDUP(no. of columns/8)) if at least one column is NULL, rounded up to a multiple of 8 | N30: =ROUNDUP((23+IF(COUNTIF(J31:J36,"Y")>0,ROUNDUP(6/8,0),0))/8,0)*8 -> 24
A31: submission_status_history | B31: 1 | C31: id | D31: bigint | E31: fixed | F31: 8 | G31: 8 | H31: Sequence identifier | I31: — | J31: N | K31: =IF(J31="Y",1,IF(E31="fixed",F31,IF(I31+1<=127,1,F31))) -> 8 | L31: =N30 -> 24 | M31: =IF(J31="Y",0,MOD(K31-MOD(L31,K31),K31)) -> 0 | N31: =L31+M31+IF(J31="Y",0,IF(E31="fixed",G31,IF(I31+1<=127,I31+1,I31+4))) -> 32 | O31: =IF(J31="Y",0,IF(E31="fixed",G31,IF(I31+1<=127,I31+1,I31+4))) -> 8
A32: submission_status_history | B32: 2 | C32: submission_id | D32: bigint | E32: fixed | F32: 8 | G32: 8 | H32: FK to submissions | I32: — | J32: N | K32: =IF(J32="Y",1,IF(E32="fixed",F32,IF(I32+1<=127,1,F32))) -> 8 | L32: =N31 -> 32 | M32: =IF(J32="Y",0,MOD(K32-MOD(L32,K32),K32)) -> 0 | N32: =L32+M32+IF(J32="Y",0,IF(E32="fixed",G32,IF(I32+1<=127,I32+1,I32+4))) -> 40 | O32: =IF(J32="Y",0,IF(E32="fixed",G32,IF(I32+1<=127,I32+1,I32+4))) -> 8
A33: submission_status_history | B33: 3 | C33: new_status | D33: submission_status (ENUM) | E33: fixed | F33: 4 | G33: 4 | H33: ENUM = 4-byte OID | I33: — | J33: N | K33: =IF(J33="Y",1,IF(E33="fixed",F33,IF(I33+1<=127,1,F33))) -> 4 | L33: =N32 -> 40 | M33: =IF(J33="Y",0,MOD(K33-MOD(L33,K33),K33)) -> 0 | N33: =L33+M33+IF(J33="Y",0,IF(E33="fixed",G33,IF(I33+1<=127,I33+1,I33+4))) -> 44 | O33: =IF(J33="Y",0,IF(E33="fixed",G33,IF(I33+1<=127,I33+1,I33+4))) -> 4
A34: submission_status_history | B34: 4 | C34: change_timestamp | D34: timestamp(3) | E34: fixed | F34: 8 | G34: 8 | H34: Change timestamp | I34: — | J34: N | K34: =IF(J34="Y",1,IF(E34="fixed",F34,IF(I34+1<=127,1,F34))) -> 8 | L34: =N33 -> 44 | M34: =IF(J34="Y",0,MOD(K34-MOD(L34,K34),K34)) -> 4 | N34: =L34+M34+IF(J34="Y",0,IF(E34="fixed",G34,IF(I34+1<=127,I34+1,I34+4))) -> 56 | O34: =IF(J34="Y",0,IF(E34="fixed",G34,IF(I34+1<=127,I34+1,I34+4))) -> 8
A35: submission_status_history | B35: 5 | C35: changed_by | D35: varchar(50) | E35: varlena | F35: 4 | G35: — | H35: Technical account (e.g. datacapture-batch) | I35: 17 | J35: N | K35: =IF(J35="Y",1,IF(E35="fixed",F35,IF(I35+1<=127,1,F35))) -> 1 | L35: =N34 -> 56 | M35: =IF(J35="Y",0,MOD(K35-MOD(L35,K35),K35)) -> 0 | N35: =L35+M35+IF(J35="Y",0,IF(E35="fixed",G35,IF(I35+1<=127,I35+1,I35+4))) -> 74 | O35: =IF(J35="Y",0,IF(E35="fixed",G35,IF(I35+1<=127,I35+1,I35+4))) -> 18
A36: submission_status_history | B36: 6 | C36: new_processing_status | D36: processing_status (ENUM) | E36: fixed | F36: 4 | G36: 4 | H36: ENUM = 4-byte OID | I36: — | J36: N | K36: =IF(J36="Y",1,IF(E36="fixed",F36,IF(I36+1<=127,1,F36))) -> 4 | L36: =N35 -> 74 | M36: =IF(J36="Y",0,MOD(K36-MOD(L36,K36),K36)) -> 2 | N36: =L36+M36+IF(J36="Y",0,IF(E36="fixed",G36,IF(I36+1<=127,I36+1,I36+4))) -> 80 | O36: =IF(J36="Y",0,IF(E36="fixed",G36,IF(I36+1<=127,I36+1,I36+4))) -> 4
C37: Step 2 – sum of the stored column sizes (B) | N37: =SUM(O31:O36) -> 50
C38: Step 2 – sum of alignment padding (B) | N38: =SUM(M31:M36) -> 6
C39: Step 3 – end of the last column (B) | N39: =N36 -> 80
C40: Step 4 – tuple aligned to MAXALIGN 8 (B) | N40: =ROUNDUP(N36/8,0)*8 -> 80
C41: Step 4 – + ItemId line pointer (B) | N41: =N40+4 -> 84
C42: Step 5 – rows per 8 KB page | N42: =INT((Assumptions!$B$16-Assumptions!$B$17)/N41) -> 97
C43: Step 5 – EFFECTIVE ROW SIZE (B) | N43: =Assumptions!$B$16/N42 -> 84.453608
...

Sheet Index calc
A1: Index size calculation per row
A2: B-tree entry = 8 B IndexTuple header + key, rounded to 8, + 4 B pointer. With deduplication (PG 13+, repeated values): one key + a list of 6 B TIDs, cost shared across n rows. Usable page = (8,192 − 24 − 16) × 90% fillfactor.
A4: Table | B4: Index | C4: Column(s) | D4: Key type | E4: Key size (B) | F4: Dedup.? | G4: Rows per key (n) | H4: Entry per row (B) | I4: Effective size per row (B) | J4: Comment
A5: submissions | B5: submissions_pkey | C5: id | D5: bigint | E5: 8 | F5: N | G5: 1 | H5: =IF(F5="Y",(ROUNDUP((8+E5+6*G5)/8,0)*8+4)/G5,ROUNDUP((8+E5)/8,0)*8+4) -> 20 | I5: =H5*Assumptions!$B$16/((Assumptions!$B$16-24-Assumptions!$B$18)*Assumptions!$B$19) -> 22.331262 | J5: One entry per row
A6: submissions | B6: ukg7wx331nfoxbc53x8g8k2x02a (UNIQUE) | C6: uuid | D6: varchar 36 chars | E6: 37 | F6: N | G6: 1 | H6: =IF(F6="Y",(ROUNDUP((8+E6+6*G6)/8,0)*8+4)/G6,ROUNDUP((8+E6)/8,0)*8+4) -> 52 | I6: =H6*Assumptions!$B$16/((Assumptions!$B$16-24-Assumptions!$B$18)*Assumptions!$B$19) -> 58.06128 | J6: One entry per row
A7: submissions | B7: idx1y0y6t7vasjgay6dtwvhh9m5b | C7: source | D7: varchar 3 chars – 4 values | E7: 4 | F7: Y | G7: 100 | H7: =IF(F7="Y",(ROUNDUP((8+E7+6*G7)/8,0)*8+4)/G7,ROUNDUP((8+E7)/8,0)*8+4) -> 6.2 | I7: =H7*Assumptions!$B$16/((Assumptions!$B$16-24-Assumptions!$B$18)*Assumptions!$B$19) -> 6.9226911 | J7: Deduplication: cost ≈ 6 B per row
A8: submissions | B8: idx2uyks9w6p1klev8s28329gheb | C8: upload_ts DESC | D8: timestamp | E8: 8 | F8: N | G8: 1 | H8: =IF(F8="Y",(ROUNDUP((8+E8+6*G8)/8,0)*8+4)/G8,ROUNDUP((8+E8)/8,0)*8+4) -> 20 | I8: =H8*Assumptions!$B$16/((Assumptions!$B$16-24-Assumptions!$B$18)*Assumptions!$B$19) -> 22.331262 | J8: One entry per row
A9: submissions | B9: idx6tj3to5q0pe6fcmykumkq3790 | C9: status | D9: ENUM – 7 values | E9: 4 | F9: Y | G9: 100 | H9: =IF(F9="Y",(ROUNDUP((8+E9+6*G9)/8,0)*8+4)/G9,ROUNDUP((8+E9)/8,0)*8+4) -> 6.2 | I9: =H9*Assumptions!$B$16/((Assumptions!$B$16-24-Assumptions!$B$18)*Assumptions!$B$19) -> 6.9226911 | J9: Deduplication: cost ≈ 6 B per row
A10: submissions | B10: idx_submissions_uuid | C10: user_id | D10: varchar 8 chars – few values | E10: 9 | F10: Y | G10: 100 | H10: =IF(F10="Y",(ROUNDUP((8+E10+6*G10)/8,0)*8+4)/G10,ROUNDUP((8+E10)/8,0)*8+4) -> 6.28 | I10: =H10*Assumptions!$B$16/((Assumptions!$B$16-24-Assumptions!$B$18)*Assumptions!$B$19) -> 7.0120161 | J10: Deduplication: cost ≈ 6 B per row
A11: submission_status_history | B11: submission_status_history_pkey | C11: id | D11: bigint | E11: 8 | F11: N | G11: 1 | H11: =IF(F11="Y",(ROUNDUP((8+E11+6*G11)/8,0)*8+4)/G11,ROUNDUP((8+E11)/8,0)*8+4) -> 20 | I11: =H11*Assumptions!$B$16/((Assumptions!$B$16-24-Assumptions!$B$18)*Assumptions!$B$19) -> 22.331262 | J11: One entry per row
A12: submission_status_history | B12: ssh_change_timestamp | C12: change_timestamp DESC | D12: timestamp | E12: 8 | F12: N | G12: 1 | H12: =IF(F12="Y",(ROUNDUP((8+E12+6*G12)/8,0)*8+4)/G12,ROUNDUP((8+E12)/8,0)*8+4) -> 20 | I12: =H12*Assumptions!$B$16/((Assumptions!$B$16-24-Assumptions!$B$18)*Assumptions!$B$19) -> 22.331262 | J12: One entry per row
A13: submission_status_history | B13: ssh_changed_by | C13: changed_by | D13: varchar 17 chars – a few accounts | E13: 18 | F13: Y | G13: 100 | H13: =IF(F13="Y",(ROUNDUP((8+E13+6*G13)/8,0)*8+4)/G13,ROUNDUP((8+E13)/8,0)*8+4) -> 6.36 | I13: =H13*Assumptions!$B$16/((Assumptions!$B$16-24-Assumptions!$B$18)*Assumptions!$B$19) -> 7.1013412 | J13: Deduplication: cost ≈ 6 B per row
A14: submission_status_history | B14: ssh_submission_id | C14: submission_id | D14: bigint – 8 rows per value | E14: 8 | F14: Y | G14: 8 | H14: =IF(F14="Y",(ROUNDUP((8+E14+6*G14)/8,0)*8+4)/G14,ROUNDUP((8+E14)/8,0)*8+4) -> 8.5 | I14: =H14*Assumptions!$B$16/((Assumptions!$B$16-24-Assumptions!$B$18)*Assumptions!$B$19) -> 9.4907862 | J14: Deduplication: cost ≈ 6 B per row
A15: metadata | B15: metadata_pkey | C15: id | D15: bigint | E15: 8 | F15: N | G15: 1 | H15: =IF(F15="Y",(ROUNDUP((8+E15+6*G15)/8,0)*8+4)/G15,ROUNDUP((8+E15)/8,0)*8+4) -> 20 | I15: =H15*Assumptions!$B$16/((Assumptions!$B$16-24-Assumptions!$B$18)*Assumptions!$B$19) -> 22.331262 | J15: One entry per row
A16: metadata | B16: idx2q7jtfxutufaqpuo77yd8ujhc | C16: extension | D16: varchar 3 chars – < 10 values | E16: 4 | F16: Y | G16: 100 | H16: =IF(F16="Y",(ROUNDUP((8+E16+6*G16)/8,0)*8+4)/G16,ROUNDUP((8+E16)/8,0)*8+4) -> 6.2 | I16: =H16*Assumptions!$B$16/((Assumptions!$B$16-24-Assumptions!$B$18)*Assumptions!$B$19) -> 6.9226911 | J16: Deduplication: cost ≈ 6 B per row
... A27: batch_step_execution_context | B27: batch_step_execution_context_pkey | C27: step_execution_id | D27: bigint | E27: 8 | F27: N | G27: 1 | H27: =IF(F27="Y",(ROUNDUP((8+E27+6*G27)/8,0)*8+4)/G27,ROUNDUP((8+E27)/8,0)*8+4) -> 20 | I27: =H27*Assumptions!$B$16/((Assumptions!$B$16-24-Assumptions!$B$18)*Assumptions!$B$19) -> 22.331262 | J27: One entry per row

Sheet Table analysis
A1: Detailed table analysis (excluding norm)
A2: Columns D–F: from the calculation sheets. Yellow columns H–J: production measurements (query Q1). K = table_size / row_count.
A4: Table | B4: Unit | C4: Rows / unit | D4: Effective row size (B) | E4: Index / row (B) | F4: Bytes / unit (data + indexes) | G4: No. of indexes | H4: Measured rows | I4: Measured data (MB) | J4: Measured indexes (MB) | K4: Measured avg row size (B) | L4: Rows in 5 years | M4: Size in 5 years (MB) | N4: Share of 5-year total | O4: Criticality | P4: Archiving | Q4: Partitioning | R4: DBA comment
A5: submissions | B5: File | C5: 1 | D5: ='Row size calc'!N25 -> 273.06667 | E5: =SUMIF('Index calc'!$A$5:$A$27,A5,'Index calc'!$I$5:$I$27) -> 123.5812 | F5: =C5*(D5+E5) -> 396.64787 | G5: =COUNTIF('Index calc'!$A$5:$A$27,A5) -> 6 | K5: =IF(AND(N(H5)>0,N(I5)>0),I5*1048576/H5,"") | L5: =C5*'5-year projection'!$C$11 -> 1373647.5 | M5: =L5*(D5+E5)*Assumptions!$B$15/1048576 -> 623.53632 | N5: =M5/$M$17 -> 0.15262256 | O5: Critical | P5: Yes (> 13 months) | Q5: No | R5: Hub table, 6 to 10 status UPDATEs per file: bloat; unindexed FKs.
A6: submission_status_history | B6: File | C6: =Assumptions!$B$14 -> 8 | D6: ='Row size calc'!N43 -> 84.453608 | E6: =SUMIF('Index calc'!$A$5:$A$27,A6,'Index calc'!$I$5:$I$27) -> 61.254651 | F6: =C6*(D6+E6) -> 1165.6661 | G6: =COUNTIF('Index calc'!$A$5:$A$27,A6) -> 4 | K6: =IF(AND(N(H6)>0,N(I6)>0),I6*1048576/H6,"") | L6: =C6*'5-year projection'!$C$11 -> 10989180 | M6: =L6*(D6+E6)*Assumptions!$B$15/1048576 -> 1832.4443 | N6: =M6/$M$17 -> 0.44852613 | O6: Critical | P6: Yes (> 13 months) | Q6: Yes if > 10 M rows (monthly RANGE) | R6: Largest table: 8 rows per file, insert-only.
A7: metadata | B7: File | C7: 1 | D7: ='Row size calc'!N61 -> 84.453608 | E7: =SUMIF('Index calc'!$A$5:$A$27,A7,'Index calc'!$I$5:$I$27) -> 82.84898 | F7: =C7*(D7+E7) -> 167.30259 | G7: =COUNTIF('Index calc'!$A$5:$A$27,A7) -> 4 | K7: =IF(AND(N(H7)>0,N(I7)>0),I7*1048576/H7,"") | L7: =C7*'5-year projection'!$C$11 -> 1373647.5 | M7: =L7*(D7+E7)*Assumptions!$B$15/1048576 -> 263.00215 | N7: =M7/$M$17 -> 0.064374854 | O7: Major | P7: Yes (with submissions) | Q7: No | R7: Purge to be orchestrated after submissions (FK without ON DELETE).
A8: preprocessing_steps | B8: File | C8: 1 | D8: ='Row size calc'!N85 -> 240.94118 | E8: =SUMIF('Index calc'!$A$5:$A$27,A8,'Index calc'!$I$5:$I$27) -> 22.331262 | F8: =C8*(D8+E8) -> 263.27244 | G8: =COUNTIF('Index calc'!$A$5:$A$27,A8) -> 1 | K8: =IF(AND(N(H8)>0,N(I8)>0),I8*1048576/H8,"") | L8: =C8*'5-year projection'!$C$11 -> 1373647.5 | M8: =L8*(D8+E8)*Assumptions!$B$15/1048576 -> 413.86817 | N8: =M8/$M$17 -> 0.10130223 | O8: Major | P8: Yes (with submissions) | Q8: No | R8: Widest row of the business tables (COS path + 6 text fields).
A9: extraction_steps | B9: File | C9: 1 | D9: ='Row size calc'!N105 -> 199.80488 | E9: =SUMIF('Index calc'!$A$5:$A$27,A9,'Index calc'!$I$5:$I$27) -> 62.527532 | F9: =C9*(D9+E9) -> 262.33241 | G9: =COUNTIF('Index calc'!$A$5:$A$27,A9) -> 2 | K9: =IF(AND(N(H9)>0,N(I9)>0),I9*1048576/H9,"") | L9: =C9*'5-year projection'!$C$11 -> 1373647.5 | M9: =L9*(D9+E9)*Assumptions!$B$15/1048576 -> 412.39043 | N9: =M9/$M$17 -> 0.10094052 | O9: Major | P9: Yes (with submissions) | Q9: No | R9: Inverted cascade to submissions.
A10: Spring Batch tables (unit = one job execution)
A11: batch_job_instance | B11: Execution | C11: 1 | D11: ='Row size calc'!N121 -> 101.1358 | E11: =SUMIF('Index calc'!$A$5:$A$27,A11,'Index calc'!$I$5:$I$27) -> 98.257551 | F11: =C11*(D11+E11) -> 199.39335 | G11: =COUNTIF('Index calc'!$A$5:$A$27,A11) -> 2 | K11: =IF(AND(N(H11)>0,N(I11)>0),I11*1048576/H11,"") | L11: =C11*Assumptions!$B$21*365*Assumptions!$B$7 -> 350400 | M11: =L11*(D11+E11)*Assumptions!$B$15/1048576 -> 79.956929 | N11: =M11/$M$17 -> 0.019571002 | O11: Major | P11: 90-day purge | Q11: No | R11: One instance per execution with RunIdIncrementer.
A12: batch_job_execution | B12: Execution | C12: 1 | D12: ='Row size calc'!N143 -> 109.22667 | E12: =SUMIF('Index calc'!$A$5:$A$27,A12,'Index calc'!$I$5:$I$27) -> 22.331262 | F12: =C12*(D12+E12) -> 131.55793 | G12: =COUNTIF('Index calc'!$A$5:$A$27,A12) -> 1 | K12: =IF(AND(N(H12)>0,N(I12)>0),I12*1048576/H12,"") | L12: =C12*Assumptions!$B$21*365*Assumptions!$B$7 -> 350400 | M12: =L12*(D12+E12)*Assumptions!$B$15/1048576 -> 52.754858 | N12: =M12/$M$17 -> 0.01291277 | O12: Major | P12: 90-day purge | Q12: No | R12: FK job_instance_id not indexed.
A13: batch_job_execution_params | B13: Execution | C13: =Assumptions!$B$22 -> 2 | D13: ='Row size calc'!N160 -> 76.560748 | E13: =SUMIF('Index calc'!$A$5:$A$27,A13,'Index calc'!$I$5:$I$27) -> 0 | F13: =C13*(D13+E13) -> 153.1215 | G13: =COUNTIF('Index calc'!$A$5:$A$27,A13) -> 0 | K13: =IF(AND(N(H13)>0,N(I13)>0),I13*1048576/H13,"") | L13: =C13*Assumptions!$B$21*365*Assumptions!$B$7 -> 700800 | M13: =L13*(D13+E13)*Assumptions!$B$15/1048576 -> 61.401869 | N13: =M13/$M$17 -> 0.015029293 | O13: Major | P13: 90-day purge | Q13: No | R13: No index: seq scan.
A14: batch_step_execution | B14: Execution | C14: =Assumptions!$B$23 -> 1 | D14: ='Row size calc'!N191 -> 199.80488 | E14: =SUMIF('Index calc'!$A$5:$A$27,A14,'Index calc'!$I$5:$I$27) -> 22.331262 | F14: =C14*(D14+E14) -> 222.13614 | G14: =COUNTIF('Index calc'!$A$5:$A$27,A14) -> 1 | K14: =IF(AND(N(H14)>0,N(I14)>0),I14*1048576/H14,"") | L14: =C14*Assumptions!$B$21*365*Assumptions!$B$7 -> 350400 | M14: =L14*(D14+E14)*Assumptions!$B$15/1048576 -> 89.076809 | N14: =M14/$M$17 -> 0.021803269 | O14: Major | P14: 90-day purge | Q14: No | R14: FK job_execution_id not indexed.
A15: batch_job_execution_context | B15: Execution | C15: 1 | D15: ='Row size calc'!N206 -> 141.24138 | E15: =SUMIF('Index calc'!$A$5:$A$27,A15,'Index calc'!$I$5:$I$27) -> 22.331262 | F15: =C15*(D15+E15) -> 163.57264 | G15: =COUNTIF('Index calc'!$A$5:$A$27,A15) -> 1 | K15: =IF(AND(N(H15)>0,N(I15)>0),I15*1048576/H15,"") | L15: =C15*Assumptions!$B$21*365*Assumptions!$B$7 -> 350400 | M15: =L15*(D15+E15)*Assumptions!$B$15/1048576 -> 65.592789 | N15: =M15/$M$17 -> 0.016055102 | O15: Moderate | P15: 90-day purge | Q15: No | R15: Short context in short_context.
A16: batch_step_execution_context | B16: Execution | C16: =Assumptions!$B$23 -> 1 | D16: ='Row size calc'!N221 -> 455.11111 | E16: =SUMIF('Index calc'!$A$5:$A$27,A16,'Index calc'!$I$5:$I$27) -> 22.331262 | F16: =C16*(D16+E16) -> 477.44237 | G16: =COUNTIF('Index calc'!$A$5:$A$27,A16) -> 1 | K16: =IF(AND(N(H16)>0,N(I16)>0),I16*1048576/H16,"") | L16: =C16*Assumptions!$B$21*365*Assumptions!$B$7 -> 350400 | M16: =L16*(D16+E16)*Assumptions!$B$15/1048576 -> 191.45486 | N16: =M16/$M$17 -> 0.046862273 | O16: Moderate | P16: 90-day purge | Q16: No | R16: Largest Spring Batch row (context > 126 B: 4 B header).
A17: TOTAL | L17: =SUM(L5:L16) -> 18936570 | M17: =SUM(M5:M16) -> 4085.4795
A19: Input example: submissions → H = 48,000 rows, I = 12.6 MB, J = 5.7 MB ⇒ K ≈ 275 bytes/row.

Sheet 5-year projection
A1: Annual projection 2027–2031: 225,000 files in 2027, +10% per year, 2 MB PDF
A3: Files in 2027 | D3: =Assumptions!$B$5 -> 225000
A4: Annual growth | D4: =Assumptions!$B$6 -> 0.1
A6: Year | B6: Annual number of PDFs | C6: Cumulative number of PDFs | D6: Average PDF size (MB) | E6: Annual PDF volume – COS (GB) | F6: Cumulative PDF volume – COS (GB) | G6: Growth % | H6: Database data (MB) | I6: Estimated index size (MB) | J6: Spring Batch without purge (MB) | K6: Total database size (MB) | L6: Estimated backup size (MB) | M6: Backup storage with retention (GB) | N6: Extraction JSON – cumulative COS (GB) | O6: Total cumulative COS (GB)
A7: =""&(Assumptions!$B$8+1) -> 2027 | B7: =$D$3 -> 225000 | C7: =B7 -> 225000 | D7: =Assumptions!$B$9 -> 2 | E7: =B7*D7/1024 -> 439.45312 | F7: =C7*D7/1024 -> 439.45312 | G7: Base | H7: =Assumptions!$B$12*(1-Assumptions!$B$13)+C7*Assumptions!$B$41*Assumptions!$B$15/1048576 -> 412.01632 | I7: =Assumptions!$B$12*Assumptions!$B$13+C7*Assumptions!$B$42*Assumptions!$B$15/1048576 -> 218.68529 | J7: =1*Assumptions!$B$21*365*Assumptions!$B$43*Assumptions!$B$15/1048576 -> 108.04762 | K7: =H7+I7+J7 -> 738.74923 | L7: =K7*Assumptions!$B$26 -> 221.62477 | M7: =(L7*Assumptions!$B$27+K7*Assumptions!$B$28*Assumptions!$B$26*Assumptions!$B$29)/1024 -> 3.1815275 | N7: =C7*Assumptions!$B$10/1048576 -> 6.4373016 | O7: =F7+N7 -> 445.89043
A8: =""&(Assumptions!$B$8+2) -> 2028 | B8: =B7*(1+$D$4) -> 247500 | C8: =C7+B8 -> 472500 | D8: =Assumptions!$B$9 -> 2 | E8: =B8*D8/1024 -> 483.39844 | F8: =C8*D8/1024 -> 922.85156 | G8: =B8/B7-1 -> 0.1 | H8: =Assumptions!$B$12*(1-Assumptions!$B$13)+C8*Assumptions!$B$41*Assumptions!$B$15/1048576 -> 829.48427 | I8: =Assumptions!$B$12*Assumptions!$B$13+C8*Assumptions!$B$42*Assumptions!$B$15/1048576 -> 439.98911 | J8: =2*Assumptions!$B$21*365*Assumptions!$B$43*Assumptions!$B$15/1048576 -> 216.09524 | K8: =H8+I8+J8 -> 1485.5686 | L8: =K8*Assumptions!$B$26 -> 445.67059 | M8: =(L8*Assumptions!$B$27+K8*Assumptions!$B$28*Assumptions!$B$26*Assumptions!$B$29)/1024 -> 6.3978102 | N8: =C8*Assumptions!$B$10/1048576 -> 13.518333 | O8: =F8+N8 -> 936.3699
A9: =""&(Assumptions!$B$8+3) -> 2029 | B9: =B8*(1+$D$4) -> 272250 | C9: =C8+B9 -> 744750 | D9: =Assumptions!$B$9 -> 2 | E9: =B9*D9/1024 -> 531.73828 | F9: =C9*D9/1024 -> 1454.5898 | G9: =B9/B8-1 -> 0.1 | H9: =Assumptions!$B$12*(1-Assumptions!$B$13)+C9*Assumptions!$B$41*Assumptions!$B$15/1048576 -> 1288.699 | I9: =Assumptions!$B$12*Assumptions!$B$13+C9*Assumptions!$B$42*Assumptions!$B$15/1048576 -> 683.42332 | J9: =3*Assumptions!$B$21*365*Assumptions!$B$43*Assumptions!$B$15/1048576 -> 324.14287 | K9: =H9+I9+J9 -> 2296.2652 | L9: =K9*Assumptions!$B$26 -> 688.87956 | M9: =(L9*Assumptions!$B$27+K9*Assumptions!$B$28*Assumptions!$B$26*Assumptions!$B$29)/1024 -> 9.889189 | N9: =C9*Assumptions!$B$10/1048576 -> 21.307468 | O9: =F9+N9 -> 1475.8973
A10: =""&(Assumptions!$B$8+4) -> 2030 | B10: =B9*(1+$D$4) -> 299475 | C10: =C9+B10 -> 1044225 | D10: =Assumptions!$B$9 -> 2 | E10: =B10*D10/1024 -> 584.91211 | F10: =C10*D10/1024 -> 2039.502 | G10: =B10/B9-1 -> 0.1 | H10: =Assumptions!$B$12*(1-Assumptions!$B$13)+C10*Assumptions!$B$41*Assumptions!$B$15/1048576 -> 1793.8352 | I10: =Assumptions!$B$12*Assumptions!$B$13+C10*Assumptions!$B$42*Assumptions!$B$15/1048576 -> 951.20094 | J10: =4*Assumptions!$B$21*365*Assumptions!$B$43*Assumptions!$B$15/1048576 -> 432.19049 | K10: =H10+I10+J10 -> 3177.2267 | L10: =K10*Assumptions!$B$26 -> 953.168 | M10: =(L10*Assumptions!$B$27+K10*Assumptions!$B$28*Assumptions!$B$26*Assumptions!$B$29)/1024 -> 13.683173 | N10: =C10*Assumptions!$B$10/1048576 -> 29.875517 | O10: =F10+N10 -> 2069.3775
A11: =""&(Assumptions!$B$8+5) -> 2031 | B11: =B10*(1+$D$4) -> 329422.5 | C11: =C10+B11 -> 1373647.5 | D11: =Assumptions!$B$9 -> 2 | E11: =B11*D11/1024 -> 643.40332 | F11: =C11*D11/1024 -> 2682.9053 | G11: =B11/B10-1 -> 0.1 | H11: =Assumptions!$B$12*(1-Assumptions!$B$13)+C11*Assumptions!$B$41*Assumptions!$B$15/1048576 -> 2349.4851 | I11: =Assumptions!$B$12*Assumptions!$B$13+C11*Assumptions!$B$42*Assumptions!$B$15/1048576 -> 1245.7563 | J11: =5*Assumptions!$B$21*365*Assumptions!$B$43*Assumptions!$B$15/1048576 -> 540.23811 | K11: =H11+I11+J11 -> 4135.4795 | L11: =K11*Assumptions!$B$26 -> 1240.6439 | M11: =(L11*Assumptions!$B$27+K11*Assumptions!$B$28*Assumptions!$B$26*Assumptions!$B$29)/1024 -> 17.810024 | N11: =C11*Assumptions!$B$10/1048576 -> 39.30037 | O11: =F11+N11 -> 2722.2056
A13: The PostgreSQL database only holds metadata; the PDF volume sits in COS (columns E, F, N, O). Current size (50 MB, 2026) included in year 2027.
A14: Spring Batch (col. J): without purge, worst case. See Capacity Planning for the 90-day purge variant.

Sheet Charts
A1: Charts – 2027–2031 (225,000 files in 2027, +10%/year)

Sheet Capacity Planning
A1: 5-year capacity planning (2031)
A4: Indicator | B4: Value | C4: Calculation rule
A5: PostgreSQL
A6: Database size in 5 years – without Spring Batch purge (MB) | B6: ='5-year projection'!K11 -> 4135.4795 | C6: Projection, year 5
A7: of which Spring Batch without purge (MB) | B7: ='5-year projection'!J11 -> 540.23811 | C7: Worst case
A8: Spring Batch with 90-day purge (MB) | B8: =Assumptions!$B$21*Assumptions!$B$24*Assumptions!$B$43*Assumptions!$B$15/1048576 -> 26.641879 | C8: executions/day × retention × bytes/execution × bloat
A9: Database size in 5 years – with purge (MB) | B9: =B6-B7+B8 -> 3621.8833 | C9: Target after purge is in place
A10: Required PGDATA disk capacity (GB) | B10: =B6*Assumptions!$B$32/1024+Assumptions!$B$33 -> 16.077108 | C10: Size without purge × margin + pg_wal reserve
A11: Recommended disk capacity (GB) | B11: =MAX(20,ROUNDUP(B10/10,0)*10) -> 20 | C11: Rounded up to the nearest 10, minimum 20 GB
A12: Warning threshold (GB used) | B12: =B11*Assumptions!$B$34 -> 14 | C12: Capacity × 70%
A13: Critical threshold (GB used) | B13: =B11*Assumptions!$B$35 -> 17 | C13: Capacity × 85%
A14: Backup
A15: Compressed full backup in 5 years (MB) | B15: ='5-year projection'!L11 -> 1240.6439 | C15: Database size × compression ratio
A16: Backup storage with retention (GB) | B16: ='5-year projection'!M11 -> 17.810024 | C16: 14 fulls + 14 days of WAL
A17: Restore
A18: Physical restore time (min) | B18: =B6*(1+Assumptions!$B$28)/Assumptions!$B$30/60 -> 0.72370891 | C18: (database + 1 day of WAL) / throughput
A19: Logical restore time pg_restore (min) | B19: =B18*4 -> 2.8948357 | C19: ≈ ×4: index rebuild
A20: COS object storage
A21: Cumulative COS volume in 5 years (GB) | B21: ='5-year projection'!O11 -> 2722.2056 | C21: PDF + JSON
A22: Recommended COS volume with margin (TB) | B22: =B21*(1+Assumptions!$B$36)/1024 -> 3.1900847 | C22: +20 %
A24: Operational alert thresholds
A25: Metric | B25: Warning / Critical | C25: Source
A26: PGDATA disk usage | B26: 70 % / 85 % | C26: System monitoring
A27: Failed WAL archiving | B27: > 0 / > 3 consecutive | C27: pg_stat_archiver.failed_count
A28: Age of the oldest XID | B28: > 500 M / > 1 000 M | C28: age(datfrozenxid)
A29: Longest transaction | B29: > 5 min / > 30 min | C29: pg_stat_activity.xact_start
A30: Sessions idle in transaction | B30: > 2 min / > 10 min | C30: pg_stat_activity.state
A31: Connections used | B31: > 70% / > 90% of max_connections | C31: pg_stat_activity
A32: Cache hit ratio | B32: < 99 % / < 95 % | C32: pg_stat_database
A33: Dead tuples on submissions | B33: > 10 % / > 20 % | C33: pg_stat_user_tables
A34: Forced checkpoints | B34: > 10 % / > 30 % | C34: pg_stat_bgwriter
A35: batch_job_execution rows | B35: > retention +10% / > 2× retention | C35: Purge check
A36: Files stuck in *_ON_HOLD | B36: > 1 h / > 4 h | C36: submissions.processing_status
A37: Last successful backup | B37: > 26 h / > 48 h | C37: Backup tool

Sheet Indexes & SQL
A1: Index analysis and recommendations
A2: Indexes that are “candidates for removal” must only be dropped after ≥ 3 months of observation (idx_scan = 0 in pg_stat_user_indexes, including on replicas).
A4: Table | B4: Finding type | C4: Priority | D4: Finding | E4: Proposed SQL command
A5: submissions | B5: Missing index (FK) | C5: P1 | D5: FK extraction_step_id with ON DELETE CASCADE without an index: each DELETE on extraction_steps scans the whole submissions table (seq scan + lock). | E5: CREATE INDEX CONCURRENTLY idx_submissions_extraction_step_id ON public.submissions (extraction_step_id);
A6: submissions | B6: Missing index (FK) | C6: P1 | D6: Same for pre_processing_step_id. | E6: CREATE INDEX CONCURRENTLY idx_submissions_pre_processing_step_id ON public.submissions (pre_processing_step_id);
A7: submissions | B7: Missing index (FK) | C7: P1 | D7: metadata_id: reverse join and future DELETE of metadata. | E7: CREATE INDEX CONCURRENTLY idx_submissions_metadata_id ON public.submissions (metadata_id);
A8: submissions | B8: Missing index (partial) | C8: P1 | D8: Hourly Algo polling (GET api/v2/submission, ON_HOLD files, batch of 100, chronological order): processing_status is not indexed → growing seq scan. | E8: CREATE INDEX CONCURRENTLY idx_submissions_onhold_upload_ts ON public.submissions (processing_status, upload_ts) WHERE processing_status IN ('PREPROCESSING_ON_HOLD','EXTRACTION_ON_HOLD','SENT_TO_FINSTAR_ON_HOLD');
A9: submissions | B9: Composite index | C9: P2 | D9: Operations monitoring / screens: combined status + date filters. | E9: CREATE INDEX CONCURRENTLY idx_submissions_status_upload_ts ON public.submissions (status, upload_ts DESC); -- then, after checking idx_scan = 0: DROP INDEX CONCURRENTLY public.idx6tj3to5q0pe6fcmykumkq3790; -- (status) alone, covered by the composite
A10: submissions | B10: Misnamed index | C10: P2 | D10: idx_submissions_uuid covers user_id, not uuid (uuid is already covered by the UNIQUE constraint). Misleading name → risk of creating a duplicate on uuid. | E10: ALTER INDEX public.idx_submissions_uuid RENAME TO idx_submissions_user_id;
A11: submissions | B11: Low-selectivity index | C11: P3 | D11: source: 4 values (API, UI, PARALLEL_RUN, CFT). Low selectivity, write cost. | E11: -- If idx_scan = 0 after 3 months: DROP INDEX CONCURRENTLY public.idx1y0y6t7vasjgay6dtwvhh9m5b; -- (source)
A12: submission_status_history | B12: Composite / redundancy | C12: P2 | D12: Reading the history of a submission sorted by date: a composite replaces the single submission_id index. | E12: CREATE INDEX CONCURRENTLY idx_ssh_submission_id_ts ON public.submission_status_history (submission_id, change_timestamp DESC); DROP INDEX CONCURRENTLY public.ssh_submission_id; -- now redundant (prefix)
A13: submission_status_history | B13: Low-selectivity index | C13: P3 | D13: changed_by: a few technical accounts. Probably unused. | E13: -- If idx_scan = 0 after 3 months: DROP INDEX CONCURRENTLY public.ssh_changed_by;
A14: submission_status_history | B14: BRIN alternative | C14: P3 | D14: Insert-only table, change_timestamp correlated with physical order: a BRIN is ~1000× smaller than a B-tree for purges by period. | E14: CREATE INDEX CONCURRENTLY brin_ssh_change_timestamp ON public.submission_status_history USING brin (change_timestamp); -- then drop ssh_change_timestamp if only range queries use it
A15: metadata | B15: Low-selectivity index | C15: P3 | D15: extension: < 10 values (extension_type domain). | E15: -- If idx_scan = 0 after 3 months: DROP INDEX CONCURRENTLY public.idx2q7jtfxutufaqpuo77yd8ujhc; -- (extension)
... A22: All | B22: Storage | C22: P2 | D22: Tables with heavy status updates: leave room in pages for HOT updates and reduce bloat. | E22: ALTER TABLE public.submissions SET (fillfactor = 85, autovacuum_vacuum_scale_factor = 0.02, autovacuum_analyze_scale_factor = 0.01); -- effective for new pages; pg_repack for existing ones

Sheet Collection queries
A1: Collection queries (to be run in production)
A3: Ref. | B3: Object | C3: SQL
A4: Q1 | B4: Volume by table: rows, data, indexes, average row size | C4: SELECT c.relname AS table_name, c.reltuples::bigint AS estimated_rows, pg_size_pretty(pg_total_relation_size(c.oid)) AS total_size, round(pg_relation_size(c.oid)/1048576.0, 2) AS data_mb, round(pg_indexes_size(c.oid)/1048576.0, 2) AS index_mb, round(COALESCE(pg_total_relation_size(c.reltoastrelid),0)/1048576.0, 2) AS toast_mb, CASE WHEN c.reltuples > 0 THEN round(pg_relation_size(c.oid)/c.reltuples) END AS avg_row_bytes FROM pg_class c JOIN pg_namespace n ON n.oid = c.relnamespace WHERE c.relkind IN ('r','p') AND n.nspname NOT IN ('pg_catalog','information_schema') ORDER BY pg_total_relation_size(c.oid) DESC;
A5: Q2 | B5: Largest indexes and usage | C5: SELECT schemaname, relname AS table_name, indexrelname AS index_name, pg_size_pretty(pg_relation_size(indexrelid)) AS size, idx_scan, idx_tup_read FROM pg_stat_user_indexes ORDER BY pg_relation_size(indexrelid) DESC;
A6: Q3 | B6: Unused indexes (excluding PK/UNIQUE) | C6: SELECT s.relname, s.indexrelname, s.idx_scan, pg_size_pretty(pg_relation_size(s.indexrelid)) FROM pg_stat_user_indexes s JOIN pg_index i ON i.indexrelid = s.indexrelid WHERE s.idx_scan = 0 AND NOT i.indisunique AND NOT i.indisprimary ORDER BY pg_relation_size(s.indexrelid) DESC; -- Also check the last reset date: SELECT stats_reset FROM pg_stat_database WHERE datname = current_database();
A7: Q4 | B7: Duplicate / redundant indexes (same definition) | C7: SELECT indrelid::regclass AS table_name, array_agg(indexrelid::regclass) AS duplicate_indexes FROM pg_index GROUP BY indrelid, indkey::text, COALESCE(indexprs::text,''), COALESCE(indpred::text,'') HAVING count(*) > 1;
A8: Q5 | B8: FKs without an index | C8: SELECT c.conrelid::regclass AS table_name, c.conname, a.attname FROM pg_constraint c JOIN pg_attribute a ON a.attrelid = c.conrelid AND a.attnum = c.conkey[1] WHERE c.contype = 'f' AND NOT EXISTS (SELECT 1 FROM pg_index i WHERE i.indrelid = c.conrelid AND i.indkey[0] = c.conkey[1]);
A9: Q6 | B9: Sequential vs index scans, dead tuples, autovacuum | C9: SELECT relname, seq_scan, seq_tup_read, idx_scan, n_live_tup, n_dead_tup, round(100.0*n_dead_tup/NULLIF(n_live_tup,0),1) AS pct_dead, n_tup_upd, n_tup_hot_upd, last_autovacuum, last_autoanalyze, autovacuum_count FROM pg_stat_user_tables ORDER BY seq_tup_read DESC;
A10: Q7 | B10: Audited configuration parameters | C10: SELECT name, setting, unit, source FROM pg_settings WHERE name IN ('shared_buffers','work_mem','maintenance_work_mem','effective_cache_size', 'max_connections','checkpoint_timeout','max_wal_size','min_wal_size','checkpoint_completion_target', 'wal_compression','random_page_cost','autovacuum','autovacuum_max_workers','autovacuum_naptime', 'autovacuum_vacuum_scale_factor','autovacuum_analyze_scale_factor','log_min_duration_statement', 'idle_in_transaction_session_timeout','statement_timeout','shared_preload_libraries', 'password_encryption','ssl','log_connections','log_autovacuum_min_duration','track_io_timing');
A11: Q8 | B11: Checkpoints and bgwriter | C11: SELECT checkpoints_timed, checkpoints_req, round(100.0*checkpoints_req/NULLIF(checkpoints_timed+checkpoints_req,0),1) AS pct_req, buffers_checkpoint, buffers_backend, maxwritten_clean, stats_reset FROM pg_stat_bgwriter; -- PostgreSQL 15
A12: Q9 | B12: Roles and privileges | C12: SELECT rolname, rolsuper, rolcreaterole, rolcreatedb, rolcanlogin, rolreplication, rolbypassrls, rolconnlimit, rolvaliduntil FROM pg_roles WHERE rolname !~ '^pg_' ORDER BY rolname; SELECT grantee, table_name, string_agg(privilege_type, ', ') FROM information_schema.role_table_grants WHERE table_schema = 'public' GROUP BY grantee, table_name ORDER BY 1,2;
A13: Q10 | B13: Application account actually used | C13: SELECT usename, application_name, client_addr, count(*) FROM pg_stat_activity WHERE datname = current_database() GROUP BY 1,2,3 ORDER BY 4 DESC;
A14: Q11 | B14: Business ratios (feed the assumptions) | C14: SELECT (SELECT count(*) FROM submission_status_history)::numeric / NULLIF((SELECT count(*) FROM submissions),0) AS history_rows_per_pdf, (SELECT round(avg(size)/1048576.0,3) FROM metadata) AS avg_pdf_size_mb, (SELECT count(*) FROM batch_job_execution WHERE create_time > now() - interval '7 days')/7.0 AS executions_per_day;
A15: Q12 | B15: Most expensive queries (pg_stat_statements required) | C15: SELECT left(query,120) AS query_text, calls, round(total_exec_time) AS total_ms, round(mean_exec_time,2) AS avg_ms, rows, shared_blks_read FROM pg_stat_statements ORDER BY total_exec_time DESC LIMIT 20;

Sheet Roadmap
A1: Prioritised and costed roadmap
A2: Effort in person-days (pd); cost = effort × daily rate (Assumptions sheet).
A4: Ref. | B4: Action | C4: Horizon | D4: Priority | E4: Risk addressed | F4: Effort (pd) | G4: Cost (€) | H4: Owner
A5: CT-01 | B5: Create the submissions FK indexes (CONCURRENTLY) | C5: Short term | D5: P1 | E5: R-M1 Cascades / seq scans | F5: 1 | G5: =F5*Assumptions!$B$38 -> 700 | H5: DBA
A6: CT-02 | B6: Partial ON_HOLD polling index (processing_status, upload_ts) | C6: Short term | D6: P1 | E6: R-M2 Algo polling | F6: 0.5 | G6: =F6*Assumptions!$B$38 -> 350 | H6: DBA
A7: CT-03 | B7: Fix the inverted cascade (FK submissions → *_steps) and document the relationship direction | C7: Short term | D7: P1 | E7: R-C1 Data loss | F7: 3 | G7: =F7*Assumptions!$B$38 -> 2100 | H7: Dev + DBA
A8: CT-04 | B8: Role separation: dedicated owner, application DML role, read-only role; stop using postgres | C8: Short term | D8: P1 | E8: R-C2 Security | F8: 3 | G8: =F8*Assumptions!$B$38 -> 2100 | H8: DBA + Security
A9: CT-05 | B9: Spring Batch indexes + automated purge (90-day retention) | C9: Short term | D9: P1 | E9: R-M3 Spring Batch | F9: 3 | G9: =F9*Assumptions!$B$38 -> 2100 | H9: Dev + DBA
A10: CT-06 | B10: Minor upgrade 15.10 → 15.19 (latest 15.x) | C10: Short term | D10: P1 | E10: R-M4 CVE | F10: 2 | G10: =F10*Assumptions!$B$38 -> 1400 | H10: DBA / Operations
A11: CT-07 | B11: PITR backup (pgBackRest/Barman) + documented restore test | C11: Short term | D11: P1 | E11: R-M6 Restore | F11: 4 | G11: =F11*Assumptions!$B$38 -> 2800 | H11: Operations
A12: CT-08 | B12: Enable pg_stat_statements, auto_explain, log_min_duration_statement; run the collection queries | C12: Short term | D12: P2 | E12: Steering | F12: 2 | G12: =F12*Assumptions!$B$38 -> 1400 | H12: DBA
A13: CT-09 | B13: Monitoring and alert thresholds (Capacity Planning sheet) | C13: Short term | D13: P2 | E13: Saturation | F13: 3 | G13: =F13*Assumptions!$B$38 -> 2100 | H13: Operations
A14: CT-10 | B14: Versioned migrations (Flyway/Liquibase); ddl-auto=validate in production | C14: Short term | D14: P2 | E14: R-M5 Schema drift | F14: 3 | G14: =F14*Assumptions!$B$38 -> 2100 | H14: Dev
A15: MT-01 | B15: Align ENUM / DOMAIN (drop inconsistent orphan domains) | C15: Medium term | D15: P2 | E15: R-Mo2 Consistency | F15: 1.5 | G15: =F15*Assumptions!$B$38 -> 1050 | H15: Dev + DBA
A16: MT-02 | B16: Memory / checkpoint / per-table autovacuum settings (fillfactor 85 on submissions) | C16: Medium term | D16: P2 | E16: Performance | F16: 2 | G16: =F16*Assumptions!$B$38 -> 1400 | H16: DBA
... A28: LT-05 | B28: Annual capacity planning review (3 reviews) | C28: Long term | D28: P3 | E28: Saturation | F28: 6 | G28: =F28*Assumptions!$B$38 -> 4200 | H28: DBA
B30: Summary by horizon | C30: Horizon | F30: Effort (pd) | G30: Cost (€)
B31: 0–6 months | C31: Short term | F31: =SUMIF($C$5:$C$28,C31,$F$5:$F$28) -> 24.5 | G31: =SUMIF($C$5:$C$28,C31,$G$5:$G$28) -> 17150
B32: 6–24 months | C32: Medium term | F32: =SUMIF($C$5:$C$28,C32,$F$5:$F$28) -> 26 | G32: =SUMIF($C$5:$C$28,C32,$G$5:$G$28) -> 18200
B33: 2–5 years | C33: Long term | F33: =SUMIF($C$5:$C$28,C33,$F$5:$F$28) -> 31 | G33: =SUMIF($C$5:$C$28,C33,$G$5:$G$28) -> 21700
B34: TOTAL | F34: =SUM(F5:F28) -> 81.5 | G34: =SUM(G5:G28) -> 57050
