Workbook

Sheet Synthèse
A1: 4all_datacapture – Synthèse de la volumétrie à 5 ans
A2: Base : 225 000 PDF/an. Tous les chiffres sont liés aux feuilles de calcul et aux hypothèses.
A4: Indicateur clé | B4: Unité | C4: =TEXT(Hypothèses!$B$9+0,"0") -> 2027 | D4: =TEXT(Hypothèses!$B$9+1,"0") -> 2028 | E4: =TEXT(Hypothèses!$B$9+2,"0") -> 2029 | F4: =TEXT(Hypothèses!$B$9+3,"0") -> 2030 | G4: =TEXT(Hypothèses!$B$9+4,"0") -> 2031
A5: PDF reçus dans l'année | B5: fichiers | C5: ='Volumétrie BDD'!C6 -> 225000 | D5: ='Volumétrie BDD'!D6 -> 225000 | E5: ='Volumétrie BDD'!E6 -> 225000 | F5: ='Volumétrie BDD'!F6 -> 225000 | G5: ='Volumétrie BDD'!G6 -> 225000
A6: Soumissions conservées en base | B6: lignes | C6: ='Volumétrie BDD'!C8 -> 236250 | D6: ='Volumétrie BDD'!D8 -> 472500 | E6: ='Volumétrie BDD'!E8 -> 708750 | F6: ='Volumétrie BDD'!F8 -> 945000 | G6: ='Volumétrie BDD'!G8 -> 1181250
A7: Lignes totales (tables transactionnelles) | B7: lignes | C7: ='Volumétrie BDD'!C41 -> 2504250 | D7: ='Volumétrie BDD'!D41 -> 5008500 | E7: ='Volumétrie BDD'!E41 -> 7512750 | F7: ='Volumétrie BDD'!F41 -> 10017000 | G7: ='Volumétrie BDD'!G41 -> 12521250
A8: dont SUBMISSION_STATUS_HISTORY | B8: lignes | C8: ='Volumétrie BDD'!C35 -> 1417500 | D8: ='Volumétrie BDD'!D35 -> 2835000 | E8: ='Volumétrie BDD'!E35 -> 4252500 | F8: ='Volumétrie BDD'!F35 -> 5670000 | G8: ='Volumétrie BDD'!G35 -> 7087500
A9: Taille de la base PostgreSQL | B9: Go | C9: ='Volumétrie BDD'!C43 -> 1.2996945 | D9: ='Volumétrie BDD'!D43 -> 2.0993889 | E9: ='Volumétrie BDD'!E43 -> 2.8990834 | F9: ='Volumétrie BDD'!F43 -> 3.6987778 | G9: ='Volumétrie BDD'!G43 -> 4.4984723
A10: Disque à provisionner par instance | B10: Go | C10: ='Volumétrie BDD'!C44 -> 30.428135 | D10: ='Volumétrie BDD'!D44 -> 31.570556 | E10: ='Volumétrie BDD'!E44 -> 32.712976 | F10: ='Volumétrie BDD'!F44 -> 33.855397 | G10: ='Volumétrie BDD'!G44 -> 34.997818
A11: Disque total cluster PostgreSQL | B11: Go | C11: ='Volumétrie BDD'!C45 -> 91.284405 | D11: ='Volumétrie BDD'!D45 -> 94.711667 | E11: ='Volumétrie BDD'!E45 -> 98.138929 | F11: ='Volumétrie BDD'!F45 -> 101.56619 | G11: ='Volumétrie BDD'!G45 -> 104.99345
A12: Stockage des sauvegardes PostgreSQL | B12: Go | C12: ='Volumétrie BDD'!C46 -> 3.2492362 | D12: ='Volumétrie BDD'!D46 -> 5.2484723 | E12: ='Volumétrie BDD'!E46 -> 7.2477085 | F12: ='Volumétrie BDD'!F46 -> 9.2469446 | G12: ='Volumétrie BDD'!G46 -> 11.246181
A13: Partitionnement nécessaire ? | C13: ='Volumétrie BDD'!C48 -> Non | D13: ='Volumétrie BDD'!D48 -> Non | E13: ='Volumétrie BDD'!E48 -> Non | F13: ='Volumétrie BDD'!F48 -> Non | G13: ='Volumétrie BDD'!G48 -> Non
A14: Fichiers conservés (PDF + sorties) | B14: fichiers | C14: ='Stockage fichiers'!C12 -> 850500 | D14: ='Stockage fichiers'!D12 -> 1701000 | E14: ='Stockage fichiers'!E12 -> 2551500 | F14: ='Stockage fichiers'!F12 -> 3402000 | G14: ='Stockage fichiers'!G12 -> 4252500
A15: Stockage fichiers utile | B15: To | C15: ='Stockage fichiers'!C13 -> 0.68605542 | D15: ='Stockage fichiers'!D13 -> 1.3721108 | E15: ='Stockage fichiers'!E13 -> 2.0581663 | F15: ='Stockage fichiers'!F13 -> 2.7442217 | G15: ='Stockage fichiers'!G13 -> 3.4302771
A16: Stockage fichiers brut répliqué | B16: To | C16: ='Stockage fichiers'!C14 -> 1.3721108 | D16: ='Stockage fichiers'!D14 -> 2.7442217 | E16: ='Stockage fichiers'!E14 -> 4.1163325 | F16: ='Stockage fichiers'!F14 -> 5.4884434 | G16: ='Stockage fichiers'!G14 -> 6.8605542
A18: Ratio stockage fichiers / base (année 5) | G18: =IFERROR(G15*1024/G9,0) -> 780.8437
A20: Lecture
A21: • La base PostgreSQL reste de taille modeste (quelques Go) : le flux de 225 000 PDF/an génère ~1,5 M de lignes/an, dominées par l'historique de statuts.
A22: • Le stockage des fichiers (hors base) représente l'essentiel du volume : il doit être dimensionné et gouverné séparément (stockage objet, cycle de vie, chiffrement).
A23: • Le partitionnement n'est pas requis pour la taille, mais reste recommandé pour SUBMISSION_STATUS_HISTORY si une politique de rétention/purge est définie.
A24: • Pour simuler un autre scénario, modifier uniquement les cellules bleues de la feuille « Hypothèses » (croissance, taille PDF, rétention…).

Sheet Hypothèses
A1: Projection de volumétrie 4all_datacapture – Hypothèses
A2: Cellules en bleu = saisies modifiables ; fond jaune = hypothèses clés. Toutes les autres feuilles se recalculent à partir de cette page.
A3: Légende : bleu = saisie · noir = calcul · vert = lien vers une autre feuille
A5: Paramètre | B5: Valeur | C5: Unité | D5: Source / justification
A6: 1. Flux métier
A7: PDF reçus par an (année 1) | B7: 225000 | C7: fichiers | D7: Donnée fournie par le demandeur : 225 000 PDF par an.
A8: Croissance annuelle du flux | B8: 0 | C8: % | D8: Hypothèse : flux constant (225 000/an chaque année). Saisir p.ex. 10 % pour un scénario de croissance.
A9: Première année de projection | B9: 2027 | C9: année | D9: Hypothèse : mise en production début 2027.
A10: Soumissions par PDF (resoumissions incluses) | B10: 1.05 | C10: ratio | D10: Hypothèse : 5 % de resoumissions (erreurs, nouvelles versions).
A12: 2. Ratios fonctionnels (modèle de données)
A13: PREPROCESSING_STEPS par soumission | B13: 1.1 | C13: lignes | D13: Hypothèse : 1 prétraitement + 10 % de rejeux.
A14: EXTRACTION_STEPS par soumission | B14: 1.5 | C14: lignes | D14: Hypothèse : 1 extraction + rejeux / multi-fournisseurs (EXTRACTION_PROVIDER).
A15: SUBMISSION_STATUS_HISTORY par soumission | B15: 6 | C15: lignes | D15: Hypothèse : RECEIVED → UPLOADED → PREPROCESSING → EXTRACTING → EXTRACTED → VALIDATED.
A16: METADATA par soumission | B16: 1 | C16: lignes | D16: Relation 1-1 (SUBMISSIONS.METADATA_ID).
A17: Pages moyennes par PDF | B17: 12 | C17: pages | D17: Hypothèse (TOTAL_PAGES) – utilisée pour le contrôle de cohérence.
A19: 3. Taille moyenne des lignes PostgreSQL (octets, en-tête 24 o + pointeur 4 o inclus)
A20: SUBMISSIONS | B20: 280 | C20: octets | D20: bigint id, uuid, url (~100), status, upload_ts, source, filename (~60), processing_status, metadata_id.
A21: METADATA | B21: 240 | C21: octets | D21: company_id, company_name (~40), confidentiality, document_id, document_name (~60), extension, received_at, size.
A22: PREPROCESSING_STEPS | B22: 290 | C22: octets | D22: output_file_path (~120), cleaned_document_id, format, type, provider, pages, timestamps.
A23: EXTRACTION_STEPS | B23: 250 | C23: octets | D23: output_file_path (~120), extraction_id, provider, timestamps, submission_id.
A24: SUBMISSION_STATUS_HISTORY | B24: 100 | C24: octets | D24: id, submission_id, new_status, change_timestamp (timestamptz), changed_by.
A26: 4. Facteurs PostgreSQL
A27: Ratio index / table – SUBMISSIONS | B27: 0.7 | C27: ratio | D27: PK + uid unique + status partiel + metadata_id + upload_ts.
A28: Ratio index / table – METADATA | B28: 0.4 | C28: ratio | D28: PK + document_id + company_id.
A29: Ratio index / table – PREPROCESSING_STEPS | B29: 0.35 | C29: ratio | D29: PK + submission_id (FK à indexer).
A30: Ratio index / table – EXTRACTION_STEPS | B30: 0.4 | C30: ratio | D30: PK + submission_id (FK à indexer).
A31: Ratio index / table – SUBMISSION_STATUS_HISTORY | B31: 0.9 | C31: ratio | D31: Table étroite : PK + (submission_id, change_timestamp) pèsent proportionnellement lourd.
A32: Facteur de bloat MVCC / fillfactor | B32: 1.25 | C32: x | D32: Hypothèse : 25 % d'espace mort toléré avec un autovacuum correctement réglé.
A33: Tables de référence (USERS, ROLE, PERMISSION…) + catalogue | B33: 0.5 | C33: Go | D33: Quelques milliers d'utilisateurs ; photos (USERS_PHOTO, bytea TOAST) ~100 Ko/utilisateur.
A34: Rétention des données en base | B34: 10 | C34: années | D34: Hypothèse : aucune purge sur l'horizon de 5 ans. Ramener à 3 pour simuler une purge/archivage.
A36: 5. Stockage des fichiers (hors base – OUTPUT_FILE_PATH)
A37: Taille moyenne d'un PDF source | B37: 1.5 | C37: Mo | D37: Hypothèse : PDF bancaires scannés/numériques 0,3–5 Mo.
A38: Taille moyenne d'une sortie de prétraitement | B38: 1.2 | C38: Mo | D38: Document nettoyé (CLEANED_DOCUMENT_ID) – hypothèse 80 % du source.
A39: Taille moyenne d'une sortie d'extraction | B39: 0.15 | C39: Mo | D39: JSON/XML de résultats d'extraction.
A40: Rétention des fichiers | B40: 10 | C40: années | D40: Hypothèse : conservation au-delà de 5 ans (obligations réglementaires).
A41: Facteur de réplication du stockage objet | B41: 2 | C41: x | D41: Hypothèse : réplication sur 2 sites / zones.
A43: 6. Exploitation / dimensionnement
A44: Nombre d'instances PostgreSQL (primaire + standbys) | B44: 3 | C44: instances | D44: Hypothèse : 1 primaire + 1 standby synchrone + 1 asynchrone (Patroni).
A45: Réserve WAL + fichiers temporaires par instance | B45: 20 | C45: Go | D45: max_wal_size, wal_keep_size, slots de réplication, tris sur disque.
A46: Taux de remplissage disque cible maximal | B46: 0.7 | C46: % | D46: Bonne pratique : ne pas dépasser 70 % pour absorber VACUUM FULL / REINDEX / pg_repack.
...

Sheet Volumétrie BDD
A1: Volumétrie PostgreSQL par table – projection 5 ans
A2: Stocks en fin d'année (cumul conservé selon la rétention). Tailles en Go (1 Go = 1024³ octets).
A4: Indicateur | B4: Unité | C4: =TEXT(Hypothèses!$B$9+0,"0") -> 2027 | D4: =TEXT(Hypothèses!$B$9+1,"0") -> 2028 | E4: =TEXT(Hypothèses!$B$9+2,"0") -> 2029 | F4: =TEXT(Hypothèses!$B$9+3,"0") -> 2030 | G4: =TEXT(Hypothèses!$B$9+4,"0") -> 2031
A5: Année de projection (n) | C5: 1 | D5: 2 | E5: 3 | F5: 4 | G5: 5
A6: PDF reçus dans l'année | B6: fichiers | C6: =Hypothèses!$B$7*(1+Hypothèses!$B$8)^(C5-1) -> 225000 | D6: =Hypothèses!$B$7*(1+Hypothèses!$B$8)^(D5-1) -> 225000 | E6: =Hypothèses!$B$7*(1+Hypothèses!$B$8)^(E5-1) -> 225000 | F6: =Hypothèses!$B$7*(1+Hypothèses!$B$8)^(F5-1) -> 225000 | G6: =Hypothèses!$B$7*(1+Hypothèses!$B$8)^(G5-1) -> 225000
A7: Soumissions créées dans l'année | B7: lignes | C7: =C6*Hypothèses!$B$10 -> 236250 | D7: =D6*Hypothèses!$B$10 -> 236250 | E7: =E6*Hypothèses!$B$10 -> 236250 | F7: =F6*Hypothèses!$B$10 -> 236250 | G7: =G6*Hypothèses!$B$10 -> 236250
A8: Soumissions conservées (stock fin d'année) | B8: lignes | C8: =SUMPRODUCT(($C$5:$C$5>C$5-Hypothèses!$B$34)*$C$7:C7) -> 236250 | D8: =SUMPRODUCT(($C$5:$D$5>D$5-Hypothèses!$B$34)*$C$7:D7) -> 472500 | E8: =SUMPRODUCT(($C$5:$E$5>E$5-Hypothèses!$B$34)*$C$7:E7) -> 708750 | F8: =SUMPRODUCT(($C$5:$F$5>F$5-Hypothèses!$B$34)*$C$7:F7) -> 945000 | G8: =SUMPRODUCT(($C$5:$G$5>G$5-Hypothèses!$B$34)*$C$7:G7) -> 1181250
A10: SUBMISSIONS
A11: Lignes (stock) | B11: lignes | C11: =C8 -> 236250 | D11: =D8 -> 472500 | E11: =E8 -> 708750 | F11: =F8 -> 945000 | G11: =G8 -> 1181250
A12: Taille table (heap, bloat inclus) | B12: Go | C12: =C11*Hypothèses!$B$20*Hypothèses!$B$32/1073741824 -> 0.077008735 | D12: =D11*Hypothèses!$B$20*Hypothèses!$B$32/1073741824 -> 0.15401747 | E12: =E11*Hypothèses!$B$20*Hypothèses!$B$32/1073741824 -> 0.23102621 | F12: =F11*Hypothèses!$B$20*Hypothèses!$B$32/1073741824 -> 0.30803494 | G12: =G11*Hypothèses!$B$20*Hypothèses!$B$32/1073741824 -> 0.38504368
A13: Taille index | B13: Go | C13: =C12*Hypothèses!$B$27 -> 0.053906115 | D13: =D12*Hypothèses!$B$27 -> 0.10781223 | E13: =E12*Hypothèses!$B$27 -> 0.16171834 | F13: =F12*Hypothèses!$B$27 -> 0.21562446 | G13: =G12*Hypothèses!$B$27 -> 0.26953057
A14: Total table + index | B14: Go | C14: =C12+C13 -> 0.13091485 | D14: =D12+D13 -> 0.2618297 | E14: =E12+E13 -> 0.39274455 | F14: =F12+F13 -> 0.5236594 | G14: =G12+G13 -> 0.65457425
A16: METADATA
A17: Lignes (stock) | B17: lignes | C17: =C8*Hypothèses!$B$16 -> 236250 | D17: =D8*Hypothèses!$B$16 -> 472500 | E17: =E8*Hypothèses!$B$16 -> 708750 | F17: =F8*Hypothèses!$B$16 -> 945000 | G17: =G8*Hypothèses!$B$16 -> 1181250
A18: Taille table (heap, bloat inclus) | B18: Go | C18: =C17*Hypothèses!$B$21*Hypothèses!$B$32/1073741824 -> 0.066007487 | D18: =D17*Hypothèses!$B$21*Hypothèses!$B$32/1073741824 -> 0.13201497 | E18: =E17*Hypothèses!$B$21*Hypothèses!$B$32/1073741824 -> 0.19802246 | F18: =F17*Hypothèses!$B$21*Hypothèses!$B$32/1073741824 -> 0.26402995 | G18: =G17*Hypothèses!$B$21*Hypothèses!$B$32/1073741824 -> 0.33003744
A19: Taille index | B19: Go | C19: =C18*Hypothèses!$B$28 -> 0.026402995 | D19: =D18*Hypothèses!$B$28 -> 0.05280599 | E19: =E18*Hypothèses!$B$28 -> 0.079208985 | F19: =F18*Hypothèses!$B$28 -> 0.10561198 | G19: =G18*Hypothèses!$B$28 -> 0.13201497
A20: Total table + index | B20: Go | C20: =C18+C19 -> 0.092410482 | D20: =D18+D19 -> 0.18482096 | E20: =E18+E19 -> 0.27723145 | F20: =F18+F19 -> 0.36964193 | G20: =G18+G19 -> 0.46205241
A22: PREPROCESSING_STEPS
A23: Lignes (stock) | B23: lignes | C23: =C8*Hypothèses!$B$13 -> 259875 | D23: =D8*Hypothèses!$B$13 -> 519750 | E23: =E8*Hypothèses!$B$13 -> 779625 | F23: =F8*Hypothèses!$B$13 -> 1039500 | G23: =G8*Hypothèses!$B$13 -> 1299375
A24: Taille table (heap, bloat inclus) | B24: Go | C24: =C23*Hypothèses!$B$22*Hypothèses!$B$32/1073741824 -> 0.087734952 | D24: =D23*Hypothèses!$B$22*Hypothèses!$B$32/1073741824 -> 0.1754699 | E24: =E23*Hypothèses!$B$22*Hypothèses!$B$32/1073741824 -> 0.26320486 | F24: =F23*Hypothèses!$B$22*Hypothèses!$B$32/1073741824 -> 0.35093981 | G24: =G23*Hypothèses!$B$22*Hypothèses!$B$32/1073741824 -> 0.43867476
A25: Taille index | B25: Go | C25: =C24*Hypothèses!$B$29 -> 0.030707233 | D25: =D24*Hypothèses!$B$29 -> 0.061414466 | E25: =E24*Hypothèses!$B$29 -> 0.0921217 | F25: =F24*Hypothèses!$B$29 -> 0.12282893 | G25: =G24*Hypothèses!$B$29 -> 0.15353617
A26: Total table + index | B26: Go | C26: =C24+C25 -> 0.11844219 | D26: =D24+D25 -> 0.23688437 | E26: =E24+E25 -> 0.35532656 | F26: =F24+F25 -> 0.47376874 | G26: =G24+G25 -> 0.59221093
A28: EXTRACTION_STEPS
A29: Lignes (stock) | B29: lignes | C29: =C8*Hypothèses!$B$14 -> 354375 | D29: =D8*Hypothèses!$B$14 -> 708750 | E29: =E8*Hypothèses!$B$14 -> 1063125 | F29: =F8*Hypothèses!$B$14 -> 1417500 | G29: =G8*Hypothèses!$B$14 -> 1771875
A30: Taille table (heap, bloat inclus) | B30: Go | C30: =C29*Hypothèses!$B$23*Hypothèses!$B$32/1073741824 -> 0.1031367 | D30: =D29*Hypothèses!$B$23*Hypothèses!$B$32/1073741824 -> 0.2062734 | E30: =E29*Hypothèses!$B$23*Hypothèses!$B$32/1073741824 -> 0.3094101 | F30: =F29*Hypothèses!$B$23*Hypothèses!$B$32/1073741824 -> 0.4125468 | G30: =G29*Hypothèses!$B$23*Hypothèses!$B$32/1073741824 -> 0.5156835
A31: Taille index | B31: Go | C31: =C30*Hypothèses!$B$30 -> 0.04125468 | D31: =D30*Hypothèses!$B$30 -> 0.082509359 | E31: =E30*Hypothèses!$B$30 -> 0.12376404 | F31: =F30*Hypothèses!$B$30 -> 0.16501872 | G31: =G30*Hypothèses!$B$30 -> 0.2062734
A32: Total table + index | B32: Go | C32: =C30+C31 -> 0.14439138 | D32: =D30+D31 -> 0.28878276 | E32: =E30+E31 -> 0.43317414 | F32: =F30+F31 -> 0.57756552 | G32: =G30+G31 -> 0.72195689
A34: SUBMISSION_STATUS_HISTORY
A35: Lignes (stock) | B35: lignes | C35: =C8*Hypothèses!$B$15 -> 1417500 | D35: =D8*Hypothèses!$B$15 -> 2835000 | E35: =E8*Hypothèses!$B$15 -> 4252500 | F35: =F8*Hypothèses!$B$15 -> 5670000 | G35: =G8*Hypothèses!$B$15 -> 7087500
A36: Taille table (heap, bloat inclus) | B36: Go | C36: =C35*Hypothèses!$B$24*Hypothèses!$B$32/1073741824 -> 0.16501872 | D36: =D35*Hypothèses!$B$24*Hypothèses!$B$32/1073741824 -> 0.33003744 | E36: =E35*Hypothèses!$B$24*Hypothèses!$B$32/1073741824 -> 0.49505616 | F36: =F35*Hypothèses!$B$24*Hypothèses!$B$32/1073741824 -> 0.66007487 | G36: =G35*Hypothèses!$B$24*Hypothèses!$B$32/1073741824 -> 0.82509359
A37: Taille index | B37: Go | C37: =C36*Hypothèses!$B$31 -> 0.14851685 | D37: =D36*Hypothèses!$B$31 -> 0.29703369 | E37: =E36*Hypothèses!$B$31 -> 0.44555054 | F37: =F36*Hypothèses!$B$31 -> 0.59406739 | G37: =G36*Hypothèses!$B$31 -> 0.74258423
A38: Total table + index | B38: Go | C38: =C36+C37 -> 0.31353557 | D38: =D36+D37 -> 0.62707113 | E38: =E36+E37 -> 0.9406067 | F38: =F36+F37 -> 1.2541423 | G38: =G36+G37 -> 1.5676778
A40: SYNTHÈSE BASE DE DONNÉES
A41: Lignes totales (tables transactionnelles) | B41: lignes | C41: =C11+C17+C23+C29+C35 -> 2504250 | D41: =D11+D17+D23+D29+D35 -> 5008500 | E41: =E11+E17+E23+E29+E35 -> 7512750 | F41: =F11+F17+F23+F29+F35 -> 10017000 | G41: =G11+G17+G23+G29+G35 -> 12521250
A42: Tables de référence + catalogue | B42: Go | C42: =Hypothèses!$B$33 -> 0.5 | D42: =Hypothèses!$B$33 -> 0.5 | E42: =Hypothèses!$B$33 -> 0.5 | F42: =Hypothèses!$B$33 -> 0.5 | G42: =Hypothèses!$B$33 -> 0.5
A43: Taille de la base | B43: Go | C43: =C14+C20+C26+C32+C38+C42 -> 1.2996945 | D43: =D14+D20+D26+D32+D38+D42 -> 2.0993889 | E43: =E14+E20+E26+E32+E38+E42 -> 2.8990834 | F43: =F14+F20+F26+F32+F38+F42 -> 3.6987778 | G43: =G14+G20+G26+G32+G38+G42 -> 4.4984723
A44: Disque à provisionner par instance | B44: Go | C44: =(C43+Hypothèses!$B$45)/Hypothèses!$B$46 -> 30.428135 | D44: =(D43+Hypothèses!$B$45)/Hypothèses!$B$46 -> 31.570556 | E44: =(E43+Hypothèses!$B$45)/Hypothèses!$B$46 -> 32.712976 | F44: =(F43+Hypothèses!$B$45)/Hypothèses!$B$46 -> 33.855397 | G44: =(G43+Hypothèses!$B$45)/Hypothèses!$B$46 -> 34.997818
A45: Disque total cluster (toutes instances) | B45: Go | C45: =C44*Hypothèses!$B$44 -> 91.284405 | D45: =D44*Hypothèses!$B$44 -> 94.711667 | E45: =E44*Hypothèses!$B$44 -> 98.138929 | F45: =F44*Hypothèses!$B$44 -> 101.56619 | G45: =G44*Hypothèses!$B$44 -> 104.99345
A46: Stockage des sauvegardes | B46: Go | C46: =C43*Hypothèses!$B$47 -> 3.2492362 | D46: =D43*Hypothèses!$B$47 -> 5.2484723 | E46: =E43*Hypothèses!$B$47 -> 7.2477085 | F46: =F43*Hypothèses!$B$47 -> 9.2469446 | G46: =G43*Hypothèses!$B$47 -> 11.246181
A47: Plus grosse table (Go) | B47: Go | C47: =MAX(C14,C20,C26,C32,C38) -> 0.31353557 | D47: =MAX(D14,D20,D26,D32,D38) -> 0.62707113 | E47: =MAX(E14,E20,E26,E32,E38) -> 0.9406067 | F47: =MAX(F14,F20,F26,F32,F38) -> 1.2541423 | G47: =MAX(G14,G20,G26,G32,G38) -> 1.5676778
...

Sheet Stockage fichiers
A1: Stockage des fichiers (PDF sources et sorties de traitement)
A2: Fichiers stockés hors base (stockage objet / NAS), référencés par OUTPUT_FILE_PATH. 1 To = 1024 Go.
A4: Indicateur | B4: Unité | C4: =TEXT(Hypothèses!$B$9+0,"0") -> 2027 | D4: =TEXT(Hypothèses!$B$9+1,"0") -> 2028 | E4: =TEXT(Hypothèses!$B$9+2,"0") -> 2029 | F4: =TEXT(Hypothèses!$B$9+3,"0") -> 2030 | G4: =TEXT(Hypothèses!$B$9+4,"0") -> 2031
A5: Année de projection (n) | C5: ='Volumétrie BDD'!C5 -> 1 | D5: ='Volumétrie BDD'!D5 -> 2 | E5: ='Volumétrie BDD'!E5 -> 3 | F5: ='Volumétrie BDD'!F5 -> 4 | G5: ='Volumétrie BDD'!G5 -> 5
A6: PDF reçus dans l'année | B6: fichiers | C6: ='Volumétrie BDD'!C6 -> 225000 | D6: ='Volumétrie BDD'!D6 -> 225000 | E6: ='Volumétrie BDD'!E6 -> 225000 | F6: ='Volumétrie BDD'!F6 -> 225000 | G6: ='Volumétrie BDD'!G6 -> 225000
A7: Volume PDF sources de l'année | B7: Go | C7: =C6*Hypothèses!$B$10*Hypothèses!$B$37/1024 -> 346.06934 | D7: =D6*Hypothèses!$B$10*Hypothèses!$B$37/1024 -> 346.06934 | E7: =E6*Hypothèses!$B$10*Hypothèses!$B$37/1024 -> 346.06934 | F7: =F6*Hypothèses!$B$10*Hypothèses!$B$37/1024 -> 346.06934 | G7: =G6*Hypothèses!$B$10*Hypothèses!$B$37/1024 -> 346.06934
A8: Volume sorties de prétraitement de l'année | B8: Go | C8: =C6*Hypothèses!$B$10*Hypothèses!$B$13*Hypothèses!$B$38/1024 -> 304.54102 | D8: =D6*Hypothèses!$B$10*Hypothèses!$B$13*Hypothèses!$B$38/1024 -> 304.54102 | E8: =E6*Hypothèses!$B$10*Hypothèses!$B$13*Hypothèses!$B$38/1024 -> 304.54102 | F8: =F6*Hypothèses!$B$10*Hypothèses!$B$13*Hypothèses!$B$38/1024 -> 304.54102 | G8: =G6*Hypothèses!$B$10*Hypothèses!$B$13*Hypothèses!$B$38/1024 -> 304.54102
A9: Volume sorties d'extraction de l'année | B9: Go | C9: =C6*Hypothèses!$B$10*Hypothèses!$B$14*Hypothèses!$B$39/1024 -> 51.9104 | D9: =D6*Hypothèses!$B$10*Hypothèses!$B$14*Hypothèses!$B$39/1024 -> 51.9104 | E9: =E6*Hypothèses!$B$10*Hypothèses!$B$14*Hypothèses!$B$39/1024 -> 51.9104 | F9: =F6*Hypothèses!$B$10*Hypothèses!$B$14*Hypothèses!$B$39/1024 -> 51.9104 | G9: =G6*Hypothèses!$B$10*Hypothèses!$B$14*Hypothèses!$B$39/1024 -> 51.9104
A10: Volume produit dans l'année | B10: Go | C10: =C7+C8+C9 -> 702.52075 | D10: =D7+D8+D9 -> 702.52075 | E10: =E7+E8+E9 -> 702.52075 | F10: =F7+F8+F9 -> 702.52075 | G10: =G7+G8+G9 -> 702.52075
A11: Nombre de fichiers produits dans l'année | B11: fichiers | C11: =C6*Hypothèses!$B$10*(1+Hypothèses!$B$13+Hypothèses!$B$14) -> 850500 | D11: =D6*Hypothèses!$B$10*(1+Hypothèses!$B$13+Hypothèses!$B$14) -> 850500 | E11: =E6*Hypothèses!$B$10*(1+Hypothèses!$B$13+Hypothèses!$B$14) -> 850500 | F11: =F6*Hypothèses!$B$10*(1+Hypothèses!$B$13+Hypothèses!$B$14) -> 850500 | G11: =G6*Hypothèses!$B$10*(1+Hypothèses!$B$13+Hypothèses!$B$14) -> 850500
A12: Nombre de fichiers conservés (stock) | B12: fichiers | C12: =SUMPRODUCT(($C$5:$C$5>C$5-Hypothèses!$B$40)*$C$11:C11) -> 850500 | D12: =SUMPRODUCT(($C$5:$D$5>D$5-Hypothèses!$B$40)*$C$11:D11) -> 1701000 | E12: =SUMPRODUCT(($C$5:$E$5>E$5-Hypothèses!$B$40)*$C$11:E11) -> 2551500 | F12: =SUMPRODUCT(($C$5:$F$5>F$5-Hypothèses!$B$40)*$C$11:F11) -> 3402000 | G12: =SUMPRODUCT(($C$5:$G$5>G$5-Hypothèses!$B$40)*$C$11:G11) -> 4252500
A13: Stockage utile conservé (stock) | B13: To | C13: =SUMPRODUCT(($C$5:$C$5>C$5-Hypothèses!$B$40)*$C$10:C10)/1024 -> 0.68605542 | D13: =SUMPRODUCT(($C$5:$D$5>D$5-Hypothèses!$B$40)*$C$10:D10)/1024 -> 1.3721108 | E13: =SUMPRODUCT(($C$5:$E$5>E$5-Hypothèses!$B$40)*$C$10:E10)/1024 -> 2.0581663 | F13: =SUMPRODUCT(($C$5:$F$5>F$5-Hypothèses!$B$40)*$C$10:F10)/1024 -> 2.7442217 | G13: =SUMPRODUCT(($C$5:$G$5>G$5-Hypothèses!$B$40)*$C$10:G10)/1024 -> 3.4302771
A14: Stockage brut répliqué | B14: To | C14: =C13*Hypothèses!$B$41 -> 1.3721108 | D14: =D13*Hypothèses!$B$41 -> 2.7442217 | E14: =E13*Hypothèses!$B$41 -> 4.1163325 | F14: =F13*Hypothèses!$B$41 -> 5.4884434 | G14: =G13*Hypothèses!$B$41 -> 6.8605542
